Workbook

Sheet README
A1: Extended-corpus protocol: Stage 1 execution record
A2: Manuscript: Administered Ethics (MIS Quarterly submission). Supplement to Appendix B.
A4: Sampling frame | B4: Instruments issued by the PIPC, or by other state bodies in consultation with it, 2020-08-05 to 2026-09-30.
A5: Inclusion 1 (instrument) | B5: Sanction decision; corrective or improvement recommendation incl. pre-inspection result; prior-adequacy review result; recommendation to another state body; sandbox exemption or statute adopted with PIPC participation; PIPC guidance or notice.
A6: Inclusion 2 (subject matter) | B6: (a) development, training, or deployment of AI models; (b) biometric identifiers processed for identification or authentication; (c) algorithmic inference of personal characteristics, interests, or risk.
A7: Inclusion 3 (examination) | B7: The record shows the regulator examining that processing (findings, requests, conditions, or remedies concerning it).
A8: Exclusions | B8: Security breaches without such a dimension; legislative privacy-impact assessments of draft statutes; public statements; announced plans; procedural rules; the two core PIPC decisions.
A9: Search and screening (executed) | B9: 30 documented web-search queries run 2026-10-02/03 (Query_Log); every PIPC instrument surfaced screened (Screening_Log). Round 1 queries were partly case-directed; Round 2 queries were category-directed.
A10: Search limitation | B10: Search engines are not deterministic and do not guarantee completeness. Direct programmatic access to the PIPC decision database failed (DB1-DB3).
A11: Census of decision database (not executed) | B11: Not carried out; the Stage2_Template sheet is retained as a specification for future work. The corpus is a documented purposive sample, not a census.
A13: Instrument types
A14: T1 | B14: Sanction decision (penalty surcharge, administrative fine, corrective order)
A15: T2 | B15: Corrective or improvement recommendation, incl. pre-inspection result
A16: T3 | B16: Prior-adequacy review result
A17: T4 | B17: Recommendation to another state body
A18: T5 | B18: Sandbox exemption or statute adopted with PIPC participation
A19: T6 | B19: PIPC guidance or notice
A20: Other | B20: Other (statement, plan, rule, non-PIPC body)
A22: Reason codes
A23: EX-CORE | B23: Already analyzed as a core record
A24: EX-NOAI | B24: No AI, biometric, or inferential processing examined
A25: EX-BREACH | B25: Security breach without AI, biometric, or inferential processing examined
A26: EX-NOTPIPC | B26: Not issued by or in consultation with the PIPC
A27: EX-PIPCROLE | B27: PIPC involvement not documented in sources (not verified)
A28: EX-PROC | B28: Procedural rule, not a case or authorization
A29: EX-STMT | B29: Public statement, not an instrument
A30: EX-PLANNED | B30: Announced plan; no decision by cutoff
A31: PEND | B31: Eligible; not coded

Sheet Query_Log
A1: QID | B1: Round | C1: Run date | D1: Query string (as entered) | E1: Records surfaced (RecID) | F1: Note
A2: Q01 | B2: 1 | C2: 2026-10-02/03 | D2: 개인정보보호위원회 인공지능 과징금 의결 2025 | E2: R07,R17,R18,R22,R38,R47,R48,R51
A3: Q02 | B3: 1 | C3: 2026-10-02/03 | D3: 개인정보위 딥시크 시정권고 국외이전 조사결과 | E3: R14,R20
A4: Q03 | B4: 1 | C4: 2026-10-02/03 | D4: 개인정보위 AI 서비스 사전 실태점검 결과 오픈AI 구글 메타 네이버 개선권고 2024년 3월 | E4: R10,R35
A5: Q04 | B5: 1 | C5: 2026-10-02/03 | D5: 개인정보위 메타 민감정보 종교 정치관 성적지향 광고 과징금 216억 | E5: R12,R07
A6: Q05 | B6: 1 | C6: 2026-10-02/03 | D6: 구글 메타 맞춤형 광고 행태정보 과징금 취소소송 판결 결과 서울행정법원 | E6: R07
A7: Q06 | B7: 1 | C7: 2026-10-02/03 | D7: 개인정보위 카카오페이 알리페이 NSF 스코어 과징금 의결 | E7: R13
A8: Q07 | B8: 1 | C8: 2026-10-02/03 | D8: 개인정보위 법무부 출입국 얼굴사진 인공지능 식별추적시스템 의결 과태료 시정명령 2022 | E8: R06
A9: Q08 | B9: 1 | C9: 2026-10-02/03 | D9: 헌법재판소 출입국 안면데이터 인공지능 식별추적 헌법소원 결정 2021헌마1575 | E9: R06
A10: Q09 | B10: 1 | C10: 2026-10-02/03 | D10: 개인정보위 생체정보 얼굴인식 처분 의결 과징금 2025 2026 | E10: R17,R18,R19,R21,R22,R46,R47,R49,R50
A11: Q10 | B11: 1 | C11: 2026-10-02/03 | D11: 개인정보위 AI 학습 이용자 데이터 무단 활용 제재 2026 | E11: R01,R34,R35,R45
A12: Q11 | B12: 1 | C12: 2026-10-02/03 | D12: 개인정보위 자율주행 원본 영상 AI 학습 규제샌드박스 실증특례 심의 의결 | E12: R26,R27,R28,R34,R37,R39
A13: Q12 | B13: 1 | C13: 2026-10-02/03 | D13: 개인정보위 사전적정성 검토 AI 서비스 의결 사례 보이스피싱 탐지 통화 | E13: R29,R30
... A31: Q30 | B31: 2 | C31: 2026-10-02/03 | D31: 개인정보위 AI 학습데이터 개인정보 과징금 처분 국내 기업 2025 2026 | E31: R34,R45
A32: DB1 | B32: DB | C32: 2026-10-02/03 | D32: PIPC decision board (agenda.do), page request | F32: Returned a different page (session-bound pagination); not usable
A33: DB2 | B33: DB | C33: 2026-10-02/03 | D33: PIPC decision board, keyword search via URL parameters | F33: Search parameters ignored; returned unfiltered list; not usable
A34: DB3 | B34: DB | C34: 2026-10-02/03 | D34: PIPC press-release board, keyword search via URL parameters | F34: Returned a different board; not usable

Sheet Screening_Log
A1: RecID | B1: Instrument or case | C1: Decision date | D1: Type | E1: Subject category | F1: Decision | G1: Reason code | H1: Corpus ID | I1: Note | J1: First row of corpus entry (1/0) | K1: Surfaced by (QID)
A2: R01 | B2: Scatter Lab (Lee Luda) sanction | C2: 2021-04-28 | D2: T1 | E2: a | F2: Core | G2: EX-CORE | H2: — | I2: Core record 1 | J2: =IF(AND(F2="Include",COUNTIF($H$2:H2,H2)=1),1,0) | K2: Q10
A3: R02 | B3: Worldcoin Foundation / Tools for Humanity sanction | C3: 2024-09-25 | D3: T1 | E3: b | F3: Core | G3: EX-CORE | H3: — | I3: Core record 2 | J3: =IF(AND(F3="Include",COUNTIF($H$2:H3,H3)=1),1,0) | K3: Q13, Q19
A4: R03 | B4: Facebook face-recognition templates | C4: 2021-08-25 | D4: T1 | E4: b | F4: Include | H4: D1 | J4: =IF(AND(F4="Include",COUNTIF($H$2:H4,H4)=1),1,0) | K4: Q13, Q14
A5: R04 | B5: Netflix (same session as R03) | C5: 2021-08-25 | D5: T1 | E5: none | F5: Exclude | G5: EX-NOAI | H5: — | I5: Consent before sign-up completion | J5: =IF(AND(F5="Include",COUNTIF($H$2:H5,H5)=1),1,0) | K5: Q13, Q14
A6: R05 | B6: Google improvement recommendation (same session as R03) | C6: 2021-08-25 | D6: T2 | E6: none | F6: Exclude | G6: EX-NOAI | H6: — | I6: Notice clarity | J6: =IF(AND(F6="Include",COUNTIF($H$2:H6,H6)=1),1,0) | K6: Q14
A7: R06 | B7: Ministry of Justice AI identification and tracking project | C7: 2022-04-27 | D7: T1 | E7: a; b | F7: Include | H7: D2 | I7: Constitutional Court dismissal 2026-02-26 coded as follow-up | J7: =IF(AND(F7="Include",COUNTIF($H$2:H7,H7)=1),1,0) | K7: Q07, Q08, Q13, Q28
A8: R07 | B8: Google and Meta third-party behavioral data | C8: 2022-09-14 | D8: T1 | E8: c | F8: Include | H8: D3 | I8: Court follow-up 2025-01-23 | J8: =IF(AND(F8="Include",COUNTIF($H$2:H8,H8)=1),1,0) | K8: Q01, Q04, Q05, Q21
A9: R08 | B9: Meta Ireland and Instagram (earlier period) | C9: 2023-07 | D9: T1 | E9: c | F9: Include | H9: D4 | J9: =IF(AND(F9="Include",COUNTIF($H$2:H9,H9)=1),1,0) | K9: Q14, Q15, Q17
A10: R09 | B10: OpenAI (ChatGPT) | C10: 2023-07-26 | D10: T1; T2 | E10: a | F10: Include | H10: D5 | J10: =IF(AND(F10="Include",COUNTIF($H$2:H10,H10)=1),1,0) | K10: Q15, Q17
A11: R10 | B11: Pre-inspection of six LLM-based services | C11: 2024-03-27 | D11: T2 | E11: a | F11: Include | H11: D6 | J11: =IF(AND(F11="Include",COUNTIF($H$2:H11,H11)=1),1,0) | K11: Q03, Q17, Q23
A12: R11 | B12: Pre-inspection of AI application services (SK Telecom, SNOW, DeepL, VUNO) | C12: 2024-06-12 | D12: T2 | E12: a | F12: Include | H12: D7 | I12: New in protocol run | J12: =IF(AND(F12="Include",COUNTIF($H$2:H12,H12)=1),1,0) | K12: Q23
A13: R12 | B13: Meta sensitive information and advertising categories | C13: 2024-11-04 | D13: T1 | E13: c | F13: Include | H13: D8 | J13: =IF(AND(F13="Include",COUNTIF($H$2:H13,H13)=1),1,0) | K13: Q04
A14: R13 | B14: Kakao Pay, Apple, Alipay (NSF risk scores) | C14: 2025-01-22 | D14: T1 | E14: c | F14: Include | H14: D9 | I14: Court follow-up 2026-06 | J14: =IF(AND(F14="Include",COUNTIF($H$2:H14,H14)=1),1,0) | K14: Q06
A15: R14 | B15: DeepSeek pre-inspection | C15: 2025-04-23 | D15: T2 | E15: a | F15: Include | H15: D10 | J15: =IF(AND(F15="Include",COUNTIF($H$2:H15,H15)=1),1,0) | K15: Q02
A16: R15 | B16: Pre-inspection of AI digital textbooks (KERIS, Ministry of Education) | C16: 2025-05-14 | D16: T2 | E16: a | F16: Include | H16: D11 | I16: New in protocol run | J16: =IF(AND(F16="Include",COUNTIF($H$2:H16,H16)=1),1,0) | K16: Q23, Q29
A17: R16 | B17: Face authentication at mobile-phone activation (recommendation to MSIT) | C17: 2026-05-27 | D17: T4 | E17: b | F17: Include | H17: D12 | I17: New in protocol run | J17: =IF(AND(F17="Include",COUNTIF($H$2:H17,H17)=1),1,0) | K17: Q25
A18: R17 | B18: Coupang (security breach and third-party activity records) | C18: 2026-06-10 | D18: T1 | E18: c (component) | F18: Include | H18: D13 | I18: Behavioral-data component only; breach component excluded (EX-BREACH) | J18: =IF(AND(F18="Include",COUNTIF($H$2:H18,H18)=1),1,0) | K18: Q01, Q09, Q27
A19: R18 | B19: TikTok; Apple (Siri) | C19: 2026-07-22 | D19: T1 | E19: a; c | F19: Include | H19: D14 | J19: =IF(AND(F19="Include",COUNTIF($H$2:H19,H19)=1),1,0) | K19: Q01, Q09, Q20
A20: R19 | B20: Facebook provision to third parties | C20: 2020-11-25 | D20: T1 | E20: none | F20: Exclude | G20: EX-NOAI | H20: — | I20: Supreme Court confirmation 2025-03-13 used as context only | J20: =IF(AND(F20="Include",COUNTIF($H$2:H20,H20)=1),1,0) | K20: Q09, Q14
A21: R20 | B21: AliExpress overseas transfer | C21: 2024-07 | D21: T1 | E21: none | F21: Exclude | G21: EX-NOAI | H21: — | J21: =IF(AND(F21="Include",COUNTIF($H$2:H21,H21)=1),1,0) | K21: Q02
A22: R21 | B22: SK Telecom USIM breach | C22: 2025 | D22: T1 | E22: none | F22: Exclude | G22: EX-BREACH | H22: — | J22: =IF(AND(F22="Include",COUNTIF($H$2:H22,H22)=1),1,0) | K22: Q09
A23: R22 | B23: KT femtocell breach | C23: 2026-07-29 | D23: T1 | E23: none | F23: Exclude | G23: EX-BREACH | H23: — | J23: =IF(AND(F23="Include",COUNTIF($H$2:H23,H23)=1),1,0) | K23: Q01, Q09
A24: R23 | B24: Coupang Fulfillment Services employment exclusion list | C24: 2026-06-10 | D24: T1 | E24: none | F24: Exclude | G24: EX-NOAI | H24: — | I24: List-based processing of sensitive information; labor relevance noted | J24: =IF(AND(F24="Include",COUNTIF($H$2:H24,H24)=1),1,0) | K24: Q27
A25: R24 | B25: Prior-adequacy review: AI CCTV selective monitoring (Vectorsys) | C25: 2024-01-24 | D25: T3 | E25: a | F25: Include | H25: A1 | I25: New in protocol run | J25: =IF(AND(F25="Include",COUNTIF($H$2:H25,H25)=1),1,0) | K25: Q28
A26: R25 | B26: Prior-adequacy review: homomorphic-encryption statistics (Disilo, Banksalad) | C26: 2024-01-24 | D26: T3 | E26: none | F26: Exclude | G26: EX-NOAI | H26: — | J26: =IF(AND(F26="Include",COUNTIF($H$2:H26,H26)=1),1,0) | K26: Q28
A27: R26 | B27: Sandbox exemptions: original video for autonomous driving (four firms) | C27: 2024-07-31 | D27: T5 | E27: a | F27: Include | H27: A2 | I27: Merged into A2 | J27: =IF(AND(F27="Include",COUNTIF($H$2:H27,H27)=1),1,0) | K27: Q11
A28: R27 | B28: Easing of sandbox safeguard criteria for original video | C28: 2026-01-23 | D28: T5 | E28: a | F28: Include | H28: A2 | I28: Merged into A2 | J28: =IF(AND(F28="Include",COUNTIF($H$2:H28,H28)=1),1,0) | K28: Q11
A29: R28 | B29: Sandbox exemption: delivery robot original video (Neubility) | C29: 2026-05-06 | D29: T5 | E29: a | F29: Include | H29: A2 | I29: Merged into A2 | J29: =IF(AND(F29="Include",COUNTIF($H$2:H29,H29)=1),1,0) | K29: Q11
A30: R29 | B30: Prior-adequacy review: AI voice-phishing detection (SK Telecom, IBK) | C30: 2024-09 | D30: T3 | E30: a; c | F30: Include | H30: A3 | I30: Merged into A3 | J30: =IF(AND(F30="Include",COUNTIF($H$2:H30,H30)=1),1,0) | K30: Q12
A31: R30 | B31: Prior-adequacy review: AI voice-phishing detection (KT, LG Uplus) | C31: 2025-07-09 | D31: T3 | E31: a; c | F31: Include | H31: A3 | I31: Merged into A3 | J31: =IF(AND(F31="Include",COUNTIF($H$2:H31,H31)=1),1,0) | K31: Q12
A32: R31 | B32: Prior-adequacy review: Toss FacePay | C32: before 2025-03 (verify) | D32: T3 | E32: b | F32: Include | H32: A4 | I32: Date not verified | J32: =IF(AND(F32="Include",COUNTIF($H$2:H32,H32)=1),1,0) | K32: Q25, Q26
A33: R32 | B33: Prior-adequacy review: Kakao Kanana AI assistant | C33: 2025-03 | D33: T3 | E33: a | F33: Include | H33: A5 | I33: New in protocol run | J33: =IF(AND(F33="Include",COUNTIF($H$2:H33,H33)=1),1,0) | K33: Q24
A34: R33 | B34: Prior-adequacy review: Naver AI Tab search agent | C34: 2026-05-27 | D34: T3 | E34: a; c | F34: Include | H34: A6 | I34: New in protocol run | J34: =IF(AND(F34="Include",COUNTIF($H$2:H34,H34)=1),1,0) | K34: Q24
A35: R34 | B35: PIPA amendment: special provision for AI development | C35: 2026-08-20 (passed) | D35: T5 | E35: a | F35: Include | H35: A7 | J35: =IF(AND(F35="Include",COUNTIF($H$2:H35,H35)=1),1,0) | K35: Q10, Q11, Q30
A36: R35 | B36: Guide on publicly available personal data for AI | C36: 2024-07-17 | D36: T6 | E36: a | F36: Include | H36: G1 | I36: Merged into G1 | J36: =IF(AND(F36="Include",COUNTIF($H$2:H36,H36)=1),1,0) | K36: Q03, Q10, Q18
A37: R36 | B37: Guide on generative AI development and use | C37: 2025-08-06 | D37: T6 | E37: a | F37: Include | H37: G1 | I37: Merged into G1 | J37: =IF(AND(F37="Include",COUNTIF($H$2:H37,H37)=1),1,0) | K37: Q18
A38: R37 | B38: Guide on personal video information from mobile video devices | C38: verify | D38: T6 | E38: a; b | F38: Pending | G38: PEND | H38: — | I38: Eligible; not coded | J38: =IF(AND(F38="Include",COUNTIF($H$2:H38,H38)=1),1,0) | K38: Q11
A39: R38 | B39: Guide on privacy in public-sector AI transformation | C39: verify | D39: T6 | E39: a | F39: Pending | G39: PEND | H39: — | I39: Eligible; not coded | J39: =IF(AND(F39="Include",COUNTIF($H$2:H39,H39)=1),1,0) | K39: Q01
A40: R39 | B40: Sandbox exemption: AI trauma-care CCTV | C40: 2026-05-06 | D40: T5 | E40: a | F40: Exclude | G40: EX-PIPCROLE | H40: — | I40: PIPC role not documented; not verified | J40: =IF(AND(F40="Include",COUNTIF($H$2:H40,H40)=1),1,0) | K40: Q11
...

Sheet Flow
A1: Stage 1 screening flow | B1: Count
A2: Queries run (web search) | B2: =COUNTA(Query_Log!$A$2:$A$31)
A3: Direct database access attempts (unsuccessful) | B3: =COUNTIF(Query_Log!$B$2:$B$34,"DB")
A4: Candidate records screened | B4: =COUNTA(Screening_Log!$A$2:$A$55)
A5: Core records (excluded from extended corpus) | B5: =COUNTIF(Screening_Log!$F$2:$F$55,"Core")
A6: Excluded with reason code | B6: =COUNTIF(Screening_Log!$F$2:$F$55,"Exclude")
A7: Eligible, not coded | B7: =COUNTIF(Screening_Log!$F$2:$F$55,"Pending")
A8: Included records | B8: =COUNTIF(Screening_Log!$F$2:$F$55,"Include")
A9: Included corpus entries after merging | B9: =SUM(Screening_Log!$J$2:$J$55)
A10: of which decisions (D) | B10: =SUMPRODUCT((Screening_Log!$J$2:$J$55=1)*(LEFT(Screening_Log!$H$2:$H$55,1)="D"))
A11: of which authorization instruments (A) | B11: =SUMPRODUCT((Screening_Log!$J$2:$J$55=1)*(LEFT(Screening_Log!$H$2:$H$55,1)="A"))
A12: of which guidance entries (G) | B12: =SUMPRODUCT((Screening_Log!$J$2:$J$55=1)*(LEFT(Screening_Log!$H$2:$H$55,1)="G"))
A13: Check: screened = core + excluded + pending + included | B13: =IF(B4=B5+B6+B7+B8,"OK","MISMATCH")
A15: Exclusions by reason code
A16: EX-NOAI | B16: =COUNTIF(Screening_Log!$G$2:$G$55,"EX-NOAI")
A17: EX-BREACH | B17: =COUNTIF(Screening_Log!$G$2:$G$55,"EX-BREACH")
A18: EX-NOTPIPC | B18: =COUNTIF(Screening_Log!$G$2:$G$55,"EX-NOTPIPC")
A19: EX-PIPCROLE | B19: =COUNTIF(Screening_Log!$G$2:$G$55,"EX-PIPCROLE")
A20: EX-PROC | B20: =COUNTIF(Screening_Log!$G$2:$G$55,"EX-PROC")
A21: EX-STMT | B21: =COUNTIF(Screening_Log!$G$2:$G$55,"EX-STMT")
A22: EX-PLANNED | B22: =COUNTIF(Screening_Log!$G$2:$G$55,"EX-PLANNED")

Sheet Stage2_Template
A1: Legend: fill the yellow cells, one row per keyword search in the PIPC decision database (위원회 결정문). Row 3 is an example; delete it before use.
A2: Keyword | B2: Search field | C2: Date from | D2: Date to | E2: Meeting type | F2: Hits (n) | G2: Decisions opened (idxId or 의안번호) | H2: New eligible entries (RecID) | I2: Screened by | J2: Date searched | K2: Note
A3: 인공지능 | B3: 제목+내용 | C3: 2020-08-05 | D3: 2026-09-30 | E3: 전체 | F3: 12 | G3: 2025-0123; 2025-0456 | H3: R55 | I3: Author initials | J3: 2026-10-10 | K3: Example only
A4: 인공지능 | B4: 제목+내용 | C4: 2020-08-05 | D4: 2026-09-30 | E4: 전체
A5: AI | B5: 제목+내용 | C5: 2020-08-05 | D5: 2026-09-30 | E5: 전체
A6: 학습 | B6: 제목+내용 | C6: 2020-08-05 | D6: 2026-09-30 | E6: 전체
A7: 생체 | B7: 제목+내용 | C7: 2020-08-05 | D7: 2026-09-30 | E7: 전체
A8: 얼굴 | B8: 제목+내용 | C8: 2020-08-05 | D8: 2026-09-30 | E8: 전체
A9: 안면 | B9: 제목+내용 | C9: 2020-08-05 | D9: 2026-09-30 | E9: 전체
A10: 홍채 | B10: 제목+내용 | C10: 2020-08-05 | D10: 2026-09-30 | E10: 전체
A11: 지문 | B11: 제목+내용 | C11: 2020-08-05 | D11: 2026-09-30 | E11: 전체
A12: 음성 | B12: 제목+내용 | C12: 2020-08-05 | D12: 2026-09-30 | E12: 전체
A13: 행태정보 | B13: 제목+내용 | C13: 2020-08-05 | D13: 2026-09-30 | E13: 전체
A14: 민감정보 | B14: 제목+내용 | C14: 2020-08-05 | D14: 2026-09-30 | E14: 전체
A15: 프로파일 | B15: 제목+내용 | C15: 2020-08-05 | D15: 2026-09-30 | E15: 전체
... A21: 추론 | B21: 제목+내용 | C21: 2020-08-05 | D21: 2026-09-30 | E21: 전체
